<?xml version="1.0"?>
<robot xmlns:xacro="http://www.ros.org/wiki/xacro">

    <material name="white">
        <color rgba="1 1 1 1" />
    </material>

    <material name="orange">
        <color rgba="1 0.3 0.1 1" />
    </material>

    <material name="blue">
        <color rgba="0.2 0.2 1 1" />
    </material>

    <material name="black">
        <color rgba="0 0 0 1" />
    </material>

    <!-- LINK BASE -->

    <link name ="link_base">
    
    </link>

    <!-- LINK DEL CHASIS -->

    <joint name = "joint_chasis" type ="fixed">
        <parent link ="link_base"/>
        <child link ="chasis"/>
        <origin xyz="-0.1 0 0"/>
    </joint>

    <link name ="chasis">
        <visual>
            <origin xyz ="0.15 0 0.075"/>
            <geometry>
                <box size ="0.3 0.3 0.15"/>
            </geometry>
            <material name ="white"/>
        </visual>
    </link>

    <!-- LINK RUEDA IZQUIERDA -->

    <joint name = "joint_roda_esquerra" type = "continuous">
        <parent link="link_base"/>
        <child link="roda_esquerra"/>
        <origin xyz="0 0.175 0" rpy ="-${pi/2} 0 0"/>
        <axis xyz="0 0 1"/>
    
    </joint>

    <link name = "roda_esquerra">
        <visual>
            <geometry>
                <cylinder radius = "0.05" length="0.04"/>
            </geometry>
            <material name = "blue"/>
        </visual>
    </link>

    <!-- LINK RUEDA DERECHA -->

    <joint name = "joint_roda_dreta" type = "continuous">
        <parent link="link_base"/>
        <child link="roda_dreta"/>
        <origin xyz="0 -0.175 0" rpy ="${pi/2} 0 0"/>
        <axis xyz="0 0 -1"/>
    
    </joint>

    <link name = "roda_dreta">
        <visual>
            <geometry>
                <cylinder radius = "0.05" length="0.04"/>
            </geometry>
            <material name = "blue"/>
        </visual>
    </link>


</robot>