<?xml version="1.0"?>
<robot xmlns:xacro="http://www.ros.org/wiki/xacro">

    <xacro:include filename="macros_inercia.xacro"/>

    <xacro:property name="largo_chassis" value="0.250"/>
    <xacro:property name="ancho_chassis" value="0.200"/>
    <xacro:property name="altura_chassis" value="0.070"/>
    <xacro:property name="masa_chassis" value="1.0"/>
    <xacro:property name="radio_rueda" value="0.033"/>
    <xacro:property name="ancho_rueda" value="0.026"/>
    <xacro:property name="masa_rueda" value="0.05"/>
    <xacro:property name="rueda_offset_x" value="0.0755"/>
    <xacro:property name="rueda_offset_y" value="0.120"/>
    <xacro:property name="rueda_offset_z" value="0.004"/>
    <xacro:property name="radio_rueda_mobil" value="0.033"/>
    <xacro:property name="masa_rueda_mobil" value="0.01"/>
    <xacro:property name="rueda_mobil_offset_x" value="0.210"/>
    <xacro:property name="rueda_mobil_offset_z" value="-0.004"/>

    <material name="white">
        <color rgba="1 1 1 1" />
    </material>

    <material name="orange">
        <color rgba="1 0.3 0.1 1" />
    </material>

    <material name="blue">
        <color rgba="0.2 0.2 1 1" />
    </material>

    <material name="black">
        <color rgba="0 0 0 1" />
    </material>

    <!-- LINK BASE -->

    <link name ="base_link">
    
    </link>

    <!-- LINK BASE_FOOTPRINT -->

    <joint name="base_footprint_joint" type="fixed">
        <parent link="base_link"/>
        <child link="base_footprint"/>
        <origin xyz="0 0 0" rpy="0 0 0"/>
    </joint>

    <link name="base_footprint"/>


    <!-- LINK DEL CHASIS -->

    <joint name = "joint_chasis" type ="fixed">
        <parent link ="base_link"/>
        <child link ="chasis"/>
        <origin xyz="${rueda_offset_x} 0 ${rueda_offset_z}"/>
    </joint>

    <link name ="chasis">
        <visual>
            <origin xyz ="${-largo_chassis/2} 0 ${altura_chassis/2}"/>
            <geometry>
                <box size ="${largo_chassis} ${ancho_chassis} ${altura_chassis}"/>
            </geometry>
            <material name ="black"/>
        </visual>
        <collision>
            <origin xyz ="${-largo_chassis/2} 0 ${altura_chassis/2}"/>
            <geometry>
                <box size ="${largo_chassis} ${ancho_chassis} ${altura_chassis}"/>
            </geometry>
        </collision>
        <xacro:inercia_caja masa="1.0" largo="${largo_chassis}" ancho="${ancho_chassis}" altura="${altura_chassis}">
            <origin xyz="${-largo_chassis/2} 0 ${altura_chassis/2}" rpy ="0 0 0"/>
        </xacro:inercia_caja>
    </link>

    <gazebo reference="chasis">
        <material>Gazebo/Black</material>
    </gazebo>

    <!-- LINK RUEDA IZQUIERDA -->

    <joint name = "joint_roda_esquerra" type = "continuous">
        <parent link="base_link"/>
        <child link="roda_esquerra"/>
        <origin xyz="0 ${rueda_offset_y} 0" rpy ="-${pi/2} 0 0"/>
        <axis xyz="0 0 1"/>
    
    </joint>

    <link name = "roda_esquerra">
        <visual>
            <geometry>
                <cylinder radius = "${radio_rueda}" length="${ancho_rueda}"/>
            </geometry>
            <material name = "blue"/>
        </visual>
        <collision>
            <geometry>
                <cylinder radius = "${radio_rueda}" length="${ancho_rueda}"/>
            </geometry>
        </collision>
        <xacro:inercia_cilindro masa="${masa_rueda}" largo="${ancho_rueda}" radio="${radio_rueda}">
            <origin xyz="0 0 0" rpy ="0 0 0"/>
        </xacro:inercia_cilindro>
    </link>

    <gazebo reference="roda_esquerra">
        <material>Gazebo/Blue</material>
    </gazebo>


    <!-- LINK RUEDA DERECHA -->

    <joint name = "joint_roda_dreta" type = "continuous">
        <parent link="base_link"/>
        <child link="roda_dreta"/>
        <origin xyz="0 ${-rueda_offset_y} 0" rpy ="${pi/2} 0 0"/>
        <axis xyz="0 0 -1"/>
    
    </joint>

    <link name = "roda_dreta">
        <visual>
            <geometry>
                <cylinder radius = "${radio_rueda}" length="${ancho_rueda}"/>
            </geometry>
            <material name = "blue"/>
        </visual>
        <collision>
            <geometry>
                <cylinder radius = "${radio_rueda}" length="${ancho_rueda}"/>
            </geometry>
        </collision>
        <xacro:inercia_cilindro masa="${masa_rueda}" largo="${ancho_rueda}" radio="${radio_rueda}">
            <origin xyz="0 0 0" rpy ="0 0 0"/>
        </xacro:inercia_cilindro>
    </link>

    <gazebo reference="roda_dreta">
        <material>Gazebo/Blue</material>
    </gazebo>


    <!-- LINK RUEDA MÓVIL -->

    <joint name="joint_roda_mobil" type="fixed">
        <parent link="chasis"/>
        <child link="roda_mobil"/>
        <origin xyz="${-rueda_mobil_offset_x} 0 ${rueda_mobil_offset_z}"/>
    </joint>

    <link name="roda_mobil">
        <visual>
            <geometry>
                <sphere radius="${radio_rueda_mobil}"/>
            </geometry>
            <material name="black"/>
        </visual>
        <collision>
            <geometry>
                <sphere radius="${radio_rueda_mobil}"/>
            </geometry>
        </collision>
        <xacro:inercia_esfera masa="${masa_rueda_mobil}" radio="${radio_rueda_mobil}">
            <origin xyz="0 0 0" rpy ="0 0 0"/>
        </xacro:inercia_esfera>
    </link>

    <gazebo reference="roda_mobil">
        <material>Gazebo/Black</material>
        <mu1 value= "0.001"/>
        <mu2 value= "0.001"/>
    </gazebo>
</robot>